<?xml version="1.0"?>
<sdf version="1.5">
  <model name="model">
    <pose>-1.08827 -2.32025 2.24903 0 -0 0</pose>
    <link name="unit_box_2">
      <pose>0.676422 -0.058315 0.998142 0 -0 0</pose>
      <gravity>1</gravity>
      <self_collide>0</self_collide>
      <kinematic>0</kinematic>
      <visual name="unit_box_2_visual">
        <pose>0 0 0 0 -0 0</pose>
        <geometry>
          <box>
            <size>11.8887 6.43251 0.213817</size>
          </box>
        </geometry>
        <material>
          <script>
            <uri>model://hallway/materials/scripts</uri>
            <uri>model://hallway/materials/textures</uri>
            <name>Gazebo/Grey</name>
          </script>
        </material>
      </visual>
      <collision name="unit_box_2_collision">
        <geometry>
          <box>
            <size>11.8887 6.43251 0.213817</size>
          </box>
        </geometry>
        <pose>0 0 0 0 -0 0</pose>
      </collision>
    </link>
    <link name="unit_box_0_clone">
      <pose>-0.332631 -3.03844 -0.499071 0 0 -1.56509</pose>
      <gravity>1</gravity>
      <self_collide>0</self_collide>
      <kinematic>0</kinematic>
      <visual name="unit_box_0_clone_visual">
        <pose>0 0 0 0 -0 0</pose>
        <geometry>
          <box>
            <size>0.193816 9.597 2.74108</size>
          </box>
        </geometry>
        <material>
          <script>
            <uri>model://hallway/materials/scripts</uri>
            <uri>model://hallway/materials/textures</uri>
            <name>Wall/TagWall</name>
          </script>
        </material>
      </visual>
      <collision name="unit_box_0_clone_collision">
        <geometry>
          <box>
            <size>0.193816 9.597 2.74108</size>
          </box>
        </geometry>
        <pose>0 0 0 0 -0 0</pose>
      </collision>
    </link>
    <link name="unit_box_0">
      <pose>-0.343791 3.09675 -0.499071 0 0 -1.5627</pose>
      <gravity>1</gravity>
      <self_collide>0</self_collide>
      <kinematic>0</kinematic>
      <visual name="unit_box_0_visual">
        <pose>0 0 0 0 -0 0</pose>
        <geometry>
          <box>
            <size>0.193816 9.597 2.74108</size>
          </box>
        </geometry>
        <material>
          <script>
            <uri>model://hallway/materials/scripts</uri>
            <uri>model://hallway/materials/textures</uri>
            <name>Wall/TagWall</name>
          </script>
        </material>
      </visual>
      <collision name="unit_box_0_collision">
        <geometry>
          <box>
            <size>0.193816 9.597 2.74108</size>
          </box>
        </geometry>
        <pose>0 0 0 0 -0 0</pose>
      </collision>
    </link>
    <joint name="unit_box_2_JOINT_7" type="universal">
      <parent>unit_box_2</parent>
      <child>unit_box_0</child>
      <axis>
        <xyz>1 0 0</xyz>
        <use_parent_model_frame>0</use_parent_model_frame>
        <limit>
          <lower>-3.14</lower>
          <upper>3.14</upper>
        </limit>
      </axis>
      <pose>0 0 0 0 -0 0</pose>
      <axis2>
        <xyz>0 1 0</xyz>
        <use_parent_model_frame>0</use_parent_model_frame>
        <limit>
          <lower>-3.14</lower>
          <upper>3.14</upper>
        </limit>
      </axis2>
    </joint>
    <joint name="unit_box_2_JOINT_6" type="universal">
      <parent>unit_box_2</parent>
      <child>unit_box_0_clone</child>
      <axis>
        <xyz>1 0 0</xyz>
        <use_parent_model_frame>0</use_parent_model_frame>
        <limit>
          <lower>-3.14</lower>
          <upper>3.14</upper>
        </limit>
      </axis>
      <pose>0 0 0 0 -0 0</pose>
      <axis2>
        <xyz>0 1 0</xyz>
        <use_parent_model_frame>0</use_parent_model_frame>
        <limit>
          <lower>-3.14</lower>
          <upper>3.14</upper>
        </limit>
      </axis2>
    </joint>
    <joint name="unit_box_0_clone_JOINT_5" type="universal">
      <parent>unit_box_0_clone</parent>
      <child>unit_box_0</child>
      <axis>
        <xyz>1 0 0</xyz>
        <use_parent_model_frame>0</use_parent_model_frame>
        <limit>
          <lower>-3.14</lower>
          <upper>3.14</upper>
        </limit>
      </axis>
      <pose>0 0 0 0 -0 0</pose>
      <axis2>
        <xyz>0 1 0</xyz>
        <use_parent_model_frame>0</use_parent_model_frame>
        <limit>
          <lower>-3.14</lower>
          <upper>3.14</upper>
        </limit>
      </axis2>
    </joint>
    <joint name="unit_box_0_clone_JOINT_3" type="universal">
      <parent>unit_box_0_clone</parent>
      <child>unit_box_2</child>
      <axis>
        <xyz>1 0 0</xyz>
        <use_parent_model_frame>0</use_parent_model_frame>
        <limit>
          <lower>-3.14</lower>
          <upper>3.14</upper>
        </limit>
      </axis>
      <pose>0 0 0 0 -0 0</pose>
      <axis2>
        <xyz>0 1 0</xyz>
        <use_parent_model_frame>0</use_parent_model_frame>
        <limit>
          <lower>-3.14</lower>
          <upper>3.14</upper>
        </limit>
      </axis2>
    </joint>
    <joint name="unit_box_0_JOINT_2" type="universal">
      <parent>unit_box_0</parent>
      <child>unit_box_0_clone</child>
      <axis>
        <xyz>1 0 0</xyz>
        <use_parent_model_frame>0</use_parent_model_frame>
        <limit>
          <lower>-3.14</lower>
          <upper>3.14</upper>
        </limit>
      </axis>
      <pose>0 0 0 0 -0 0</pose>
      <axis2>
        <xyz>0 1 0</xyz>
        <use_parent_model_frame>0</use_parent_model_frame>
        <limit>
          <lower>-3.14</lower>
          <upper>3.14</upper>
        </limit>
      </axis2>
    </joint>
    <joint name="unit_box_0_JOINT_4" type="universal">
      <parent>unit_box_0</parent>
      <child>unit_box_2</child>
      <axis>
        <xyz>1 0 0</xyz>
        <use_parent_model_frame>0</use_parent_model_frame>
        <limit>
          <lower>-3.14</lower>
          <upper>3.14</upper>
        </limit>
      </axis>
      <pose>0 0 0 0 -0 0</pose>
      <axis2>
        <xyz>0 1 0</xyz>
        <use_parent_model_frame>0</use_parent_model_frame>
        <limit>
          <lower>-3.14</lower>
          <upper>3.14</upper>
        </limit>
      </axis2>
    </joint>
    <joint name="unit_box_2_JOINT_1" type="universal">
      <parent>unit_box_2</parent>
      <child>unit_box_0_clone</child>
      <axis>
        <xyz>1 0 0</xyz>
        <use_parent_model_frame>0</use_parent_model_frame>
        <limit>
          <lower>-3.14</lower>
          <upper>3.14</upper>
        </limit>
      </axis>
      <pose>0 0 0 0 -0 0</pose>
      <axis2>
        <xyz>0 1 0</xyz>
        <use_parent_model_frame>0</use_parent_model_frame>
        <limit>
          <lower>-3.14</lower>
          <upper>3.14</upper>
        </limit>
      </axis2>
    </joint>
    <joint name="unit_box_2_JOINT_0" type="universal">
      <parent>unit_box_2</parent>
      <child>unit_box_0</child>
      <axis>
        <xyz>1 0 0</xyz>
        <use_parent_model_frame>0</use_parent_model_frame>
        <limit>
          <lower>-3.14</lower>
          <upper>3.14</upper>
        </limit>
      </axis>
      <pose>0 0 0 0 -0 0</pose>
      <axis2>
        <xyz>0 1 0</xyz>
        <use_parent_model_frame>0</use_parent_model_frame>
        <limit>
          <lower>-3.14</lower>
          <upper>3.14</upper>
        </limit>
      </axis2>
    </joint>
    <static>1</static>
    <allow_auto_disable>1</allow_auto_disable>
  </model>
</sdf>
